Workbook

Sheet Как пользоваться
A1: Вопросы Eva CRM — анкета, интервью и итог · кастдев 2.0
A3: Вкладки | B3: Клиентки (кастдев), Эксперты, Партнёры, Амбассадоры. На каждой три блока — как три шага в CRM: 1. Анкета → 2. Созвон → 3. Итог.
A4: Разделы | B4: Вопросы клиенток — по таблице «Вопросы V2»: анкета разбита на 8 разделов (знакомство, жизнь, состояние, время для себя, режим дня, контент, Ева, на связи), интервью — на 9 (от знакомства до «посоветовала бы подруге»). Сиреневые строки — названия разделов, как в CRM.
A5: Править вопросы | B5: Меняйте текст прямо в столбце «Вопрос», варианты — в «Варианты ответа». Новый вопрос — вставьте строку внутри нужного блока. Лишний — удалите строку.
A6: Вписывать ответы | B6: Жёлтые столбцы «Человек 1, 2, 3…» — один столбец на человека. Имя из первого вопроса анкеты само встанет в заголовок столбца.
A7: Как вписывать | B7: Один вариант — выберите из списка в ячейке или впишите свой. Несколько вариантов — через запятую. «Другое» — впишите свой вариант словами. Шкала — цифра (1–10 или 1–5, см. «Как отвечать»). Дата — 14.03.1991. У вопросов интервью с быстрыми метками — сначала метка, потом ответ.
A8: Пример | B8: Серый столбец «Пример» показывает, как выглядят заполненные ответы (вымышленный человек из демо в CRM). Его можно удалить.
A9: Ответили | B9: Столбец считается сам: сколько человек ответили на вопрос.
A10: Перенести в CRM | B10: Таблица с CRM не связана. Чтобы правка вопроса попала в анкету по ссылке, повторите её в CRM: «Вопросы» → значок карандаша у вопроса. Новые ссылки сразу будут с правкой.
A12: Сводка
A13: Группа | B13: Вопросов в анкете | C13: Вопросов для созвона | D13: Людей с анкетой | E13: Созвонов проведено
A14: Клиентки (кастдев) | B14: =COUNT('Клиентки (кастдев)'!A7:A53) | C14: =COUNT('Клиентки (кастдев)'!A58:A102) | D14: =COUNTA('Клиентки (кастдев)'!G7:U7) | E14: =COUNTA('Клиентки (кастдев)'!G55:U55)
A15: Эксперты | B15: =COUNT('Эксперты'!A6:A22) | C15: =COUNT('Эксперты'!A26:A38) | D15: =COUNTA('Эксперты'!G6:P6) | E15: =COUNTA('Эксперты'!G24:P24)
A16: Партнёры | B16: =COUNT('Партнёры'!A6:A18) | C16: =COUNT('Партнёры'!A22:A31) | D16: =COUNTA('Партнёры'!G6:P6) | E16: =COUNTA('Партнёры'!G20:P20)
A17: Амбассадоры | B17: =COUNT('Амбассадоры'!A6:A19) | C17: =COUNT('Амбассадоры'!A23:A32) | D17: =COUNTA('Амбассадоры'!G6:P6) | E17: =COUNTA('Амбассадоры'!G21:P21)
A18: Всего | B18: =SUM(B14:B17) | C18: =SUM(C14:C17) | D18: =SUM(D14:D17) | E18: =SUM(E14:E17)
A20: Справочно: 14 направлений экспертов | B20: 🏋️‍♀️ Фитнес · 🤸‍♀️ Растяжка · 🧠 Психология · ☯️ Цигун · 💌 Аффирмации · 🌬 Медитация и дыхание · 👶 Для мам · 💄 Красота и здоровье · 🧭 Предназначение · 💗 Отношения · 🧘‍♀️ Йога · 🤰 Для беременных · 🌺 Женские практики · 💰 Финансы
A21: Категории партнёров | B21: 💅 Салон красоты · 🤸‍♀️ Студия пилатеса · 🧘‍♀️ Йога-студия · 🏋️‍♀️ Фитнес-клуб · ✨ Косметология · 💆‍♀️ SPA и массаж · 🥗 Здоровое питание · 🧠 Психологический центр · 🏥 Женское здоровье · 👶 Центр для мам и детей · 🏠 Пространство для встреч · 🛍 Бренд для маркета · 🎤 Организатор мероприятий · ⭐ Спонсор · 📱 Медиа и блогеры · 📚 Образование

Sheet Клиентки (кастдев)
A1: 🌸 Кастдев — клиентки
A2: Кастдев: что болит, что нравится и что улучшить в Еве. Три шага, как в CRM: Анкета → Интервью → Итог. Обращаемся на «ты».
A3: Жёлтые столбцы — для ответов, по одному на человека. Вопросы и варианты можно править прямо здесь.
A4: № | B4: Вопрос | C4: Как отвечать | D4: Варианты ответа / зачем спрашиваем | E4: Ответили | F4: Пример | G4: =IF(G$7="","Человек 1",G$7) | H4: =IF(H$7="","Человек 2",H$7) | I4: =IF(I$7="","Человек 3",I$7) | J4: =IF(J$7="","Человек 4",J$7) | K4: =IF(K$7="","Человек 5",K$7) | L4: =IF(L$7="","Человек 6",L$7) | M4: =IF(M$7="","Человек 7",M$7) | N4: =IF(N$7="","Человек 8",N$7) | O4: =IF(O$7="","Человек 9",O$7) | P4: =IF(P$7="","Человек 10",P$7) | Q4: =IF(Q$7="","Человек 11",Q$7) | R4: =IF(R$7="","Человек 12",R$7) | S4: =IF(S$7="","Человек 13",S$7) | T4: =IF(T$7="","Человек 14",T$7) | U4: =IF(U$7="","Человек 15",U$7)
B5: 1. АНКЕТА — человек заполняет сам по ссылке или вы за него
B6: 🌸 Знакомство — имя, город, возраст · 5
A7: 1 | B7: Как тебя зовут? | C7: Короткий ответ | D7: Подсказка в поле: Имя | E7: =COUNTA(G7:U7) | F7: Ольга
A8: 2 | B8: Твой EVA ID — если ты уже в приложении | C8: Короткий ответ · можно пропустить | D8: Подсказка в поле: Можно пропустить | E8: =COUNTA(G8:U8) | F8: EVA-40210
A9: 3 | B9: Когда у тебя день рождения? | C9: Дата | D9: Дата: 14.03.1991. Возраст посчитаем сами — в анкете он не нужен | E9: =COUNTA(G9:U9) | F9: 34156
A10: 4 | B10: В каком городе ты живёшь? | C10: Короткий ответ | D10: Подсказка в поле: Начни писать: Казань | E10: =COUNTA(G10:U10) | F10: Москва
A11: 5 | B11: Страна | C11: Один вариант | D11: В анкете не спрашиваем — подставляем по городу. Если город незнакомый: Россия · Казахстан · Беларусь · Узбекистан · Грузия · Армения · Другая страна (впишите своё) | E11: =COUNTA(G11:U11) | F11: Россия
B12: 🏡 Жизнь сейчас — статус, работа, доход, жильё, этап · 8
A13: 6 | B13: Твой социальный статус | C13: Несколько вариантов (до 2) | D13: Можно отметить два: статус и что ищешь. Не замужем, в отношениях не была · Замужем · Живу с партнёром без регистрации · В отношениях, живём раздельно · Всё сложно / в процессе развода · Разведена · Вдова · Не ищу отношений, фокусируюсь на себе · Ищу серьёзные отношения · Ищу лёгкое общение без обязательств · Открыта к знакомствам, но специально не ищу | E13: =COUNTA(G13:U13) | F13: Не замужем, в отношениях не была
A14: 7 | B14: Твоя занятость | C14: Один вариант | D14: Полная занятость по трудовому договору · Частичная занятость · Индивидуальный предприниматель (ИП) · Самозанятая / Фрилансер · Владелица бизнеса / Предприниматель (есть сотрудники в штате) · Руководитель / Топ-менеджер · Специалист / Линейный сотрудник · Обслуживающий / Технический персонал · Студентка · В декретном отпуске · Домохозяйка · Временно не работаю (в активном поиске работы) · Не работаю (и не ищу работу) | E14: =COUNTA(G14:U14) | F14: Владелица бизнеса / Предприниматель
A15: 8 | B15: Какой у тебя график работы? | C15: Один вариант | D15: Только тем, кто работает (по ответу о занятости). Работаю удалённо · Работаю на гибридном графике · Работаю в офисе 5/2 · Работаю по сменному графику, например 2/2 | E15: =COUNTA(G15:U15) | F15: Работаю удалённо
A16: 9 | B16: Как ты оцениваешь свой доход? | C16: Один вариант | D16: Примерно — нам важна картина, а не цифры. Крайне низкий (денег не хватает даже на продукты) · Низкий (на продукты хватает, одежда — уже трудно) · Ниже среднего (хватает на еду и одежду, технику — копить или в кредит) · Средний (хватает на еду, одежду и крупную технику, но не на машину) · Выше среднего (можем купить машину, на жильё нужна ипотека) · Высокий (можем позволить почти всё без кредитов) · На обеспечении (живу на обеспечении родителей, партнёра или государства) | E16: =COUNTA(G16:U16) | F16: Низкий
A17: 10 | B17: Где и как ты живёшь? | C17: Один вариант | D17: Собственное жильё (без ипотеки и обременений) · Собственное жильё в ипотеке · Снимаю жильё (помесячная аренда) · Живу с родителями или родственниками · Живу в общежитии · Служебное жильё (предоставил работодатель) · Временное размещение (без постоянного места жительства) | E17: =COUNTA(G17:U17) | F17: Собственное жильё
A18: 11 | B18: Какой у тебя ритм жизни? | C18: Один вариант | D18: Жаворонок — легко встаю рано · Сова — оживаю к вечеру · Где-то посередине · Свой режим, всё по ситуации · Режим скачет: дети, смены, перелёты | E18: =COUNTA(G18:U18) | F18: Где-то посередине
A19: 12 | B19: Какая сфера сейчас забирает 80% твоего внимания? | C19: Один вариант | D19: Отношения · Семья и дети · Карьера и учёба · Поиск себя и отдых | E19: =COUNTA(G19:U19) | F19: Карьера и учёба
A20: 13 | B20: Какой вариант точнее всего описывает твой этап жизни? | C20: Несколько вариантов (до 2) | D20: Второй шаг после сферы: показываем группы выбранной сферы. Выбери один или два самых актуальных. Становление, учёба и сепарация: Первое образование / Студенчество (учусь в колледже или вузе, думаю, что делать дальше) · Взросление и сепарация от родителей (первые шаги в самостоятельной жизни, свои границы) · Первый опыт работы (выхожу на рынок труда, привыкаю к взрослой ответственности) Отношения, романтика и дейтинг: В активном поиске спутника жизни (серьёзные отношения, семейные перспективы) · В поиске флирта, лёгкого общения или интрижки (без обязательств) · Этап влюблённости и романтики (начало отношений, притирка, общие планы) · Осознанно не в отношениях / Соло-жизнь (комфортно одной, фокус на себе) · Переживаю расставание / Развод (восстановление, проживание боли, пересборка себя) Материнство и семья: Беременность (подготовка к новой роли, смена приоритетов) · Мама младенца / малыша до 3 лет (большая нагрузка, мало времени на себя) · Мама дошкольника / школьника (3–12 лет: баланс семейных и своих задач) · Мама подростка / взрослого ребёнка (дети отделяются, «пустое гнездо», своя жизнь) Карьера, бизнес и реализация: Построение карьеры / Профессиональный рост (рост, статус, повышаю доход) · Развитие своего дела / Предпринимательство (много ответственности, ищу ресурс и систему) · Смена профессии / Второе образование (переучиваюсь, ищу новое дело) Поиск себя и ресурс: Ищу своё направление / В поиске себя (кризис смыслов, исследую свои желания) · В поисках баланса и защиты от выгорания (перегрузка, собираю ресурсы) · Поживу для себя / Фокус на личных интересах (замедление, эстетика, отдых) · Переходный период / Перезагрузка (переезд, смена уклада, поиск опоры) | E20: =COUNTA(G20:U20) | F20: Первый опыт работы, Смена профессии / Второе образование
B21: 🌤 Состояние — энергия, настроение, что беспокоит · 5
A22: 14 | B22: Какой у тебя сейчас уровень энергии? | C22: Шкала 1–10 | D22: 1 — полный ноль … 10 — могу всё. Подсказки: 1 — Полный «ноль» · 2 — Сильное истощение · 3 — Фоновая тревога и тяжесть · 4 — Вывожу из последних сил · 5 — Нормальный режим · 6 — Умеренный ресурс · 7 — Хороший ресурс · 8 — Высокий подъём · 9 — Изобилие и поток · 10 — Максимальный пик | E22: =COUNTA(G22:U22) | F22: 6
A23: 15 | B23: Насколько ты довольна своей жизнью сейчас? | C23: Шкала 1–10 | D23: 1 — всё рушится … 10 — полная гармония. Подсказки: 1 — Глубокий тупик · 2 — Острое недовольство · 3 — «День сурка» · 4 — Живу не на полную · 5 — 50 на 50 · 6 — Скорее довольна · 7 — Хорошая, устойчивая жизнь · 8 — Высокий уровень счастья · 9 — Полный контакт с собой · 10 — Абсолютная гармония | E23: =COUNTA(G23:U23) | F23: 7
A24: 16 | B24: Как ты оцениваешь своё здоровье? | C24: Шкала 1–10 | D24: 1 — очень плохо … 10 — отлично. Подсказки: 1 — Очень плохо · 2 — Плохо · 3 — Ниже среднего · 4 — Терпимо · 5 — Средне · 6 — Неплохо · 7 — Хорошо · 8 — Очень хорошо · 9 — Отлично · 10 — На все 100% | E24: =COUNTA(G24:U24) | F24: 5
A25: 17 | B25: Что беспокоит чаще всего? | C25: Несколько вариантов (до 2) | D25: Усталость и выгорание · Постоянная самокритика и сомнения · Проблемы со сном, сложно расслабиться · Нет времени и ресурса на себя · Одиночество и дефицит общения · Потеря ориентиров и поиск себя · Сложности в отношениях или с границами · Другое (впишите своё) | E25: =COUNTA(G25:U25) | F25: Потеря ориентиров и поиск себя, Усталость и выгорание
A26: 18 | B26: Какая сфера для тебя сейчас важнее всего? | C26: Один вариант | D26: Над чем хочется поработать в первую очередь. Ментальное здоровье и эмоциональный баланс (выгорание, тревога, покой) · Физическое здоровье, тело и тонус (восстановление ресурса, забота о себе, сон) · Романтические отношения и личная жизнь (поиск партнёра, крепкий брак, проживание расставания) · Материнство и семья (воспитание детей, баланс между домом и собой) · Карьера, бизнес и финансовая независимость (рост дохода, проявление в профессии, смена работы) · Окружение и социальные связи (поиск «своих» людей, дружба, нетворкинг) · Личностный рост и самоопределение (кризис смыслов, уверенность в себе, синдром самозванки) · Время для себя и яркость жизни (эстетичный досуг, новые увлечения, время только для себя) · В своём прайме, всё хорошо | E26: =COUNTA(G26:U26) | F26: Время для себя и яркость жизни
B27: ⏳ Время для себя — сколько, когда, что уже пробовала · 5
A28: 19 | B28: Сколько минут в день реально готова уделять себе? | C28: Один вариант | D28: 5–10 минут · 15–20 минут · 30 минут и больше | E28: =COUNTA(G28:U28) | F28: 15–20 минут
A29: 20 | B29: Когда тебе удобнее заниматься собой? | C29: Один вариант | D29: Утром · Днём · Вечером | E29: =COUNTA(G29:U29) | F29: Днём
A30: 21 | B30: Что ты уже пробовала? | C30: Несколько вариантов | D30: Приложения медитаций · Йога или фитнес · Психолог · Онлайн-курсы · Марафоны блогеров · Пока ничего · Другое (впишите своё) | E30: =COUNTA(G30:U30) | F30: Приложения медитаций, Марафоны блогеров
A31: 22 | B31: Сколько в месяц тратишь на саморазвитие: онлайн-обучение, курсы, практики, спорт? | C31: Один вариант | D31: До 3 000 ₽ · 3 000–7 000 ₽ · 7 000–15 000 ₽ · 15 000–30 000 ₽ · 30 000–60 000 ₽ · 60 000 ₽ и больше | E31: =COUNTA(G31:U31) | F31: До 3 000 ₽
A32: 23 | B32: Как тебе комфортнее меняться и проходить трансформации? | C32: Один вариант | D32: С наставником · Самостоятельно · В группе, с поддержкой · По-разному | E32: =COUNTA(G32:U32) | F32: С наставником
B33: ☀️ Режим дня — сон, питание, телефон · 6
A34: 24 | B34: Во сколько ты обычно просыпаешься? | C34: Один вариант | D34: До 6:00 · 6:00–7:00 · 7:00–8:00 · 8:00–9:00 · После 9:00 · Каждый день по-разному | E34: =COUNTA(G34:U34) | F34: 7:00–8:00
A35: 25 | B35: Во сколько ложишься спать? | C35: Один вариант | D35: До 22:00 · 22:00–23:00 · 23:00–00:00 · 00:00–01:00 · После 01:00 · По-разному | E35: =COUNTA(G35:U35) | F35: 00:00–01:00
A36: 26 | B36: Как обычно устроено твоё питание? | C36: Несколько вариантов | D36: Готовлю сама · Доставка еды · Кафе и рестораны · Перекусы на ходу · Готовит кто-то из семьи | E36: =COUNTA(G36:U36) | F36: Готовлю сама, Кафе и рестораны
A37: 27 | B37: Какой у тебя тип питания? | C37: Один вариант | D37: Ем всё · Вегетарианка · Веганка · Пескетарианка · Фрукторианка · Слежу: ПП, без сахара или глютена · Другое (впишите своё) | E37: =COUNTA(G37:U37) | F37: Ем всё
A38: 28 | B38: Сколько времени в день ты проводишь в телефоне? | C38: Один вариант | D38: Можно подсмотреть в «Экранном времени». До 2 часов · 2–4 часа · 4–6 часов · Больше 6 часов · Не знаю | E38: =COUNTA(G38:U38) | F38: Не знаю
A39: 29 | B39: Пользуешься ли трекерами здоровья? | C39: Несколько вариантов | D39: Apple Watch · Whoop · Garmin · Фитнес-браслет · Умное кольцо · Нет, ничего | E39: =COUNTA(G39:U39) | F39: Умное кольцо
B40: 📱 Контент — где и как смотришь полезное · 5
...

Sheet Эксперты
A1: 🎓 Эксперты
A2: Подключаем экспертов: что снимаем, когда и на каких условиях. Три шага, как в CRM: Анкета → Созвон → Итог. Обращаемся на «вы».
A3: Жёлтые столбцы — для ответов, по одному на человека. Вопросы и варианты можно править прямо здесь.
A4: № | B4: Вопрос | C4: Как отвечать | D4: Варианты ответа / зачем спрашиваем | E4: Ответили | F4: Пример | G4: =IF(G$6="","Человек 1",G$6) | H4: =IF(H$6="","Человек 2",H$6) | I4: =IF(I$6="","Человек 3",I$6) | J4: =IF(J$6="","Человек 4",J$6) | K4: =IF(K$6="","Человек 5",K$6) | L4: =IF(L$6="","Человек 6",L$6) | M4: =IF(M$6="","Человек 7",M$6) | N4: =IF(N$6="","Человек 8",N$6) | O4: =IF(O$6="","Человек 9",O$6) | P4: =IF(P$6="","Человек 10",P$6)
B5: 1. АНКЕТА — человек заполняет сам по ссылке или вы за него
A6: 1 | B6: Как вас зовут? ✨ | C6: Короткий ответ | D6: Подсказка в поле: Имя и фамилия | E6: =COUNTA(G6:P6) | F6: Марина Ясная
A7: 2 | B7: Ваш город 📍 | C7: Короткий ответ | D7: Подсказка в поле: Москва | E7: =COUNTA(G7:P7) | F7: Москва
A8: 3 | B8: Ваше направление в Еве — выберите до трёх | C8: Несколько вариантов (до 3) | D8: 🏋️‍♀️ Фитнес · 🤸‍♀️ Растяжка · 🧠 Психология · ☯️ Цигун · 💌 Аффирмации · 🌬 Медитация и дыхание · 👶 Для мам · 💄 Красота и здоровье · 🧭 Предназначение · 💗 Отношения · 🧘‍♀️ Йога · 🤰 Для беременных · 🌺 Женские практики · 💰 Финансы · ✨ Другое | E8: =COUNTA(G8:P8) | F8: 🧠 Психология
A9: 4 | B9: В какой теме вы эксперт? Одной фразой | C9: Короткий ответ | D9: Подсказка в поле: Например: дыхание при тревоге | E9: =COUNTA(G9:P9) | F9: Самокритика и внутренний критик
A10: 5 | B10: Сколько лет в профессии? | C10: Один вариант | D10: до года · 1–3 года · 3–5 лет · 5–10 лет · больше 10 лет | E10: =COUNTA(G10:P10) | F10: больше 10 лет
A11: 6 | B11: Образование по профилю 🎓 | C11: Один вариант | D11: Диплом по профилю · Сертификаты и курсы · Большая практика без документов | E11: =COUNTA(G11:P11) | F11: Сертификаты и курсы
A12: 7 | B12: Что у вас уже есть? 📦 | C12: Несколько вариантов | D12: 🎬 Записанный курс · 📡 Живой курс или марафон · 🎓 Мастер-классы · 🧘‍♀️ Практики и медитации · 💬 Консультации · 🏠 Офлайн-встречи и ретриты · ✨ Пока ничего | E12: =COUNTA(G12:P12) | F12: 💬 Консультации, 🧘‍♀️ Практики и медитации, 🎓 Мастер-классы, 🎬 Записанный курс
A13: 8 | B13: Хотите снять курс вместе с Евой? 🎥 | C13: Один вариант | D13: 🔥 Да, уже есть идея · 🤔 Возможно, обсудим · 📦 Есть готовый — хочу разместить · 🙅‍♀️ Пока нет | E13: =COUNTA(G13:P13) | F13: 🔥 Да, уже есть идея
A14: 9 | B14: Что можем записать с вами? 🎬 | C14: Несколько вариантов | D14: 💌 Послания и аффирмации (1–2 мин) · 🧘‍♀️ Короткие практики (5–15 мин) · 🎓 Мастер-класс (20–40 мин) · 📚 Курс · 📡 Эфир или вопрос-ответ · 🏠 Офлайн-встречу | E14: =COUNTA(G14:P14) | F14: 📚 Курс, 🎓 Мастер-класс (20–40 мин), 💌 Послания и аффирмации (1–2 мин), 🧘‍♀️ Короткие практики (5–15 мин)
A15: 10 | B15: Где удобнее снимать? | C15: Один вариант | D15: 🏙 Приеду в студию в Москве · 🎥 Есть своя качественная съёмка · 💻 Только онлайн · 🤝 Обсудим | E15: =COUNTA(G15:P15) | F15: 🎥 Есть своя качественная съёмка
A16: 11 | B16: Сколько времени готовы выделить на съёмки? 📅 | C16: Один вариант | D16: 1 день · 2–3 дня · Регулярно, раз в месяц | E16: =COUNTA(G16:P16) | F16: Регулярно, раз в месяц
A17: 12 | B17: Ваша аудитория в соцсетях 👥 | C17: Один вариант | D17: Пока нет · До 1 тыс. · 1–10 тыс. · 10–50 тыс. · Больше 50 тыс. | E17: =COUNTA(G17:P17) | F17: 10–50 тыс.
... A22: 17 | B22: Telegram или телефон для связи 📲 | C22: Короткий ответ | D22: Подсказка в поле: @username или +7… | E22: =COUNTA(G22:P22) | F22: @marina
B23: 2. СОЗВОН — открытые вопросы для Zoom, 20–30 минут. Записывайте коротко, своими словами
B24: Дата созвона | C24: Дата | D24: Например: 25.09.2026 | E24: =COUNTA(G24:P24)
B25: Кто вёл | C25: Короткий ответ | D25: Имя из команды | E25: =COUNTA(G25:P25)
A26: 1 | B26: С чем к вам чаще всего приходят женщины? Какой результат они получают? | C26: Открытый ответ | D26: Зачем: Ценность эксперта для нашей аудитории | E26: =COUNTA(G26:P26) | F26: С тревогой и ощущением «я плохая мама». Через месяц практик — спокойнее реагируют и лучше спят.
A27: 2 | B27: Как сейчас устроена ваша работа: откуда клиенты, что продаёте, что приносит больше всего? | C27: Открытый ответ | D27: Зачем: Бизнес эксперта и его мотивация | E27: =COUNTA(G27:P27)
A28: 3 | B28: Какие продукты у вас уже есть — курсы, мастер-классы, практики? Что лучше всего покупают? | C28: Открытый ответ | D28: Зачем: Готовый контент для Евы | E28: =COUNTA(G28:P28) | F28: Есть курс из 6 уроков и 10 практик. Лучше всего покупают короткие практики по 10 минут.
A29: 4 | B29: Что вы давно хотели снять, но пока не сняли? Что мешает? | C29: Открытый ответ | D29: Зачем: Идеи для совместных съёмок | E29: =COUNTA(G29:P29) | F29: Давно хочу снять курс про утренние ритуалы — нет оператора и времени на монтаж.
A30: 5 | B30: Какой опыт был с онлайн-школами и платформами? Что понравилось, что нет? | C30: Открытый ответ | D30: Зачем: Ожидания и страхи | E30: =COUNTA(G30:P30)
A31: 6 | B31: Как вы относитесь к коротким форматам: практика на 7 минут, послание на 1 минуту? | C31: Открытый ответ | D31: Зачем: Подходит ли формат Евы | E31: =COUNTA(G31:P31) | F31: Короткие форматы люблю: люди реально их делают.
A32: 7 | B32: Кто ваш идеальный клиент? Похож ли он на наших участниц — женщины 25–45? | C32: Открытый ответ | D32: Зачем: Совпадение аудиторий | E32: =COUNTA(G32:P32)
A33: 8 | B33: Какие темы в вашем направлении сейчас спрашивают чаще всего? | C33: Открытый ответ | D33: Зачем: Темы курсов с гарантированным спросом | E33: =COUNTA(G33:P33)
A34: 9 | B34: Сколько времени в месяц вы готовы отдавать Еве: съёмки, эфиры, ответы в сообществе? | C34: Открытый ответ | D34: Зачем: Реальная загрузка | E34: =COUNTA(G34:P34) | F34: Могу два съёмочных дня в месяц и эфир раз в две недели.
A35: 10 | B35: Что для вас важно в сотрудничестве: деньги, аудитория, бренд, свобода? | C35: Открытый ответ | D35: Зачем: На чём строить условия | E35: =COUNTA(G35:P35) | F35: Важно, чтобы меня указывали как автора и была прозрачная отчётность по продажам.
A36: 11 | B36: Готовы рассказать своей аудитории про Еву? Как бы вы это сделали? | C36: Открытый ответ | D36: Зачем: Эксперт как канал привлечения | E36: =COUNTA(G36:P36) | F36: Да, расскажу в канале и в сторис — у меня 12 тысяч подписчиц.
A37: 12 | B37: Что должно быть в договоре, чтобы вам было спокойно? | C37: Открытый ответ | D37: Зачем: Снять страхи заранее | E37: =COUNTA(G37:P37)
A38: 13 | B38: Кого из коллег вы бы нам порекомендовали? | C38: Открытый ответ | D38: Зачем: Следующие эксперты | E38: =COUNTA(G38:P38)
A39: + | B39: Что ещё важного прозвучало | C39: Открытый ответ | D39: Всё, что не попало в вопросы | E39: =COUNTA(G39:P39)
B40: 3. ИТОГ — сразу после созвона
B41: Решение | C41: Один вариант | D41: Подключаем · Думает · Не сейчас | E41: =COUNTA(G41:P41) | F41: Подключаем
B42: О чём договорились | C42: Несколько вариантов | D42: 💌 Послания · 🧘‍♀️ Практики · 🎓 Мастер-класс · 📚 Курс · 📡 Эфир · 🏠 Офлайн-встреча · 📦 Готовый курс · 📣 Расскажет аудитории | E42: =COUNTA(G42:P42) | F42: 🎓 Мастер-класс, 📚 Курс, 📣 Расскажет аудитории
B43: Следующий шаг | C43: Короткий ответ | D43: Например: съёмка 3 практик | E43: =COUNTA(G43:P43) | F43: Съёмка мастер-класса «Как перестать себя ругать»
B44: Когда | C44: Дата | D44: Например: 10.10.2026 | E44: =COUNTA(G44:P44)
...

Sheet Партнёры
A1: 🤝 Партнёры
A2: Салоны, студии и бренды: взаимный промо и спецпредложения. Три шага, как в CRM: Анкета → Встреча → Итог. Обращаемся на «вы».
A3: Жёлтые столбцы — для ответов, по одному на человека. Вопросы и варианты можно править прямо здесь.
A4: № | B4: Вопрос | C4: Как отвечать | D4: Варианты ответа / зачем спрашиваем | E4: Ответили | F4: Пример | G4: =IF(G$6="","Человек 1",G$6) | H4: =IF(H$6="","Человек 2",H$6) | I4: =IF(I$6="","Человек 3",I$6) | J4: =IF(J$6="","Человек 4",J$6) | K4: =IF(K$6="","Человек 5",K$6) | L4: =IF(L$6="","Человек 6",L$6) | M4: =IF(M$6="","Человек 7",M$6) | N4: =IF(N$6="","Человек 8",N$6) | O4: =IF(O$6="","Человек 9",O$6) | P4: =IF(P$6="","Человек 10",P$6)
B5: 1. АНКЕТА — человек заполняет сам по ссылке или вы за него
A6: 1 | B6: Как называется ваша компания? 🏷 | C6: Короткий ответ | D6: Подсказка в поле: Студия «Баланс» | E6: =COUNTA(G6:P6) | F6: Салон «Лаванда»
A7: 2 | B7: Категория | C7: Один вариант | D7: 💅 Салон красоты · 🤸‍♀️ Студия пилатеса · 🧘‍♀️ Йога-студия · 🏋️‍♀️ Фитнес-клуб · ✨ Косметология · 💆‍♀️ SPA и массаж · 🥗 Здоровое питание · 🧠 Психологический центр · 🏥 Женское здоровье · 👶 Центр для мам и детей · 🏠 Пространство для встреч · 🛍 Бренд для маркета · 🎤 Организатор мероприятий · ⭐ Спонсор · 📱 Медиа и блогеры · 📚 Образование | E7: =COUNTA(G7:P7) | F7: 💅 Салон красоты
A8: 3 | B8: Город 📍 | C8: Короткий ответ | D8: Подсказка в поле: Москва | E8: =COUNTA(G8:P8) | F8: Москва
A9: 4 | B9: Адрес или «онлайн» | C9: Короткий ответ | D9: Подсказка в поле: ул. Покровка, 17 | E9: =COUNTA(G9:P9) | F9: центр города
A10: 5 | B10: Контактное лицо и должность 👤 | C10: Короткий ответ | D10: Подсказка в поле: Ирина, управляющая | E10: =COUNTA(G10:P10) | F10: Ирина Громова, управляющая
A11: 6 | B11: Сколько клиенток у вас в месяц? | C11: Один вариант | D11: До 100 · 100–500 · 500–2 000 · Больше 2 000 | E11: =COUNTA(G11:P11) | F11: 100–500
A12: 7 | B12: Возраст ваших клиенток | C12: Несколько вариантов | D12: до 25 · 25–34 · 35–44 · 45+ | E12: =COUNTA(G12:P12) | F12: до 25, 35–44
A13: 8 | B13: Что вам интересно? 🤝 | C13: Несколько вариантов | D13: 🔁 Взаимный промо · 🎁 Спецпредложение для участниц Евы · 💰 Комиссия за приведённых клиенток · 🏢 Корпоративная подписка для сотрудниц · 🎬 Площадка для съёмок или встреч · 🛍 Товары в маркете Евы · 🎉 Совместное мероприятие · ⭐ Спонсорство | E13: =COUNTA(G13:P13) | F13: 🏢 Корпоративная подписка для сотрудниц, 🎁 Спецпредложение для участниц Евы
A14: 9 | B14: Что можете дать участницам Евы? 🎁 | C14: Несколько вариантов | D14: Скидку · Пробное занятие · Подарок · Бесплатную консультацию · Пока не знаю | E14: =COUNTA(G14:P14) | F14: Скидку, Бесплатную консультацию
A15: 10 | B15: Где можете рассказать о Еве? 📣 | C15: Несколько вариантов | D15: Соцсети · Рассылка клиентам · Администратор на ресепшене · Стойка или листовки · Мероприятия | E15: =COUNTA(G15:P15) | F15: Рассылка клиентам, Соцсети
A16: 11 | B16: Аудитория в соцсетях 👥 | C16: Один вариант | D16: Пока нет · До 1 тыс. · 1–10 тыс. · Больше 10 тыс. | E16: =COUNTA(G16:P16) | F16: Больше 10 тыс.
A17: 12 | B17: Когда удобно встретиться? | C17: Один вариант | D17: В будни утром · В будни днём · Вечером · Лучше в переписке | E17: =COUNTA(G17:P17) | F17: В будни днём
A18: 13 | B18: Telegram или телефон 📲 | C18: Короткий ответ | D18: Подсказка в поле: @username или +7… | E18: =COUNTA(G18:P18) | F18: @salon
B19: 2. ВСТРЕЧА — открытые вопросы для Zoom, 20–30 минут. Записывайте коротко, своими словами
B20: Дата созвона | C20: Дата | D20: Например: 25.09.2026 | E20: =COUNTA(G20:P20)
B21: Кто вёл | C21: Короткий ответ | D21: Имя из команды | E21: =COUNTA(G21:P21)
A22: 1 | B22: Расскажите о ваших клиентках: кто они, с чем приходят, что их волнует помимо вашей услуги? | C22: Открытый ответ | D22: Зачем: Совпадение с аудиторией Евы | E22: =COUNTA(G22:P22)
A23: 2 | B23: Как вы сейчас удерживаете клиенток между визитами? | C23: Открытый ответ | D23: Зачем: Где Ева может помочь партнёру | E23: =COUNTA(G23:P23)
A24: 3 | B24: Какие партнёрства у вас уже были? Что сработало, а что нет? | C24: Открытый ответ | D24: Зачем: Опыт и ожидания | E24: =COUNTA(G24:P24)
A25: 4 | B25: Что для вас выгодное партнёрство: деньги, новые клиентки, контент, имидж? | C25: Открытый ответ | D25: Зачем: Формат сотрудничества | E25: =COUNTA(G25:P25)
A26: 5 | B26: Как вы обычно рассказываете клиенткам о партнёрах? Кто это делает? | C26: Открытый ответ | D26: Зачем: Реальный канал рекомендации | E26: =COUNTA(G26:P26)
A27: 6 | B27: Какое спецпредложение вы готовы дать участницам Евы? | C27: Открытый ответ | D27: Зачем: Оффер для витрины | E27: =COUNTA(G27:P27)
A28: 7 | B28: Нужны ли вам практики или мастер-класс от Евы для ваших клиенток? | C28: Открытый ответ | D28: Зачем: Что даём мы | E28: =COUNTA(G28:P28)
A29: 8 | B29: Кто у вас принимает решение о партнёрстве и сколько это обычно занимает? | C29: Открытый ответ | D29: Зачем: Скорость запуска | E29: =COUNTA(G29:P29)
A30: 9 | B30: Что может вас остановить? | C30: Открытый ответ | D30: Зачем: Риски | E30: =COUNTA(G30:P30)
A31: 10 | B31: Как мы поймём через 3 месяца, что партнёрство удалось? | C31: Открытый ответ | D31: Зачем: Общий критерий успеха | E31: =COUNTA(G31:P31)
A32: + | B32: Что ещё важного прозвучало | C32: Открытый ответ | D32: Всё, что не попало в вопросы | E32: =COUNTA(G32:P32)
B33: 3. ИТОГ — сразу после созвона
B34: Решение | C34: Один вариант | D34: Подключаем · Думает · Не сейчас | E34: =COUNTA(G34:P34) | F34: Подключаем
B35: О чём договорились | C35: Несколько вариантов | D35: 🔁 Взаимный промо · 🎁 Спецпредложение · 💰 Комиссия · 🏢 Корпоративная подписка · 🎬 Площадка · 🛍 Маркет · 🎉 Мероприятие · ⭐ Спонсорство | E35: =COUNTA(G35:P35) | F35: 🎁 Спецпредложение, 🔁 Взаимный промо
B36: Следующий шаг | C36: Короткий ответ | D36: Например: прислать макет стойки | E36: =COUNTA(G36:P36) | F36: Стойка с QR на ресепшене
B37: Когда | C37: Дата | D37: Например: 10.10.2026 | E37: =COUNTA(G37:P37)
B38: Заметка | C38: Развёрнутый ответ | D38: Условия, договорённости, что важно помнить | E38: =COUNTA(G38:P38) | F38: −15% на уход участницам Евы по промокоду EVA15.

Sheet Амбассадоры
A1: 📣 Амбассадоры
A2: Те, кто рассказывает о Еве и приводит подруг. Три шага, как в CRM: Анкета → Созвон → Итог. Обращаемся на «ты».
A3: Жёлтые столбцы — для ответов, по одному на человека. Вопросы и варианты можно править прямо здесь.
A4: № | B4: Вопрос | C4: Как отвечать | D4: Варианты ответа / зачем спрашиваем | E4: Ответили | F4: Пример | G4: =IF(G$6="","Человек 1",G$6) | H4: =IF(H$6="","Человек 2",H$6) | I4: =IF(I$6="","Человек 3",I$6) | J4: =IF(J$6="","Человек 4",J$6) | K4: =IF(K$6="","Человек 5",K$6) | L4: =IF(L$6="","Человек 6",L$6) | M4: =IF(M$6="","Человек 7",M$6) | N4: =IF(N$6="","Человек 8",N$6) | O4: =IF(O$6="","Человек 9",O$6) | P4: =IF(P$6="","Человек 10",P$6)
B5: 1. АНКЕТА — человек заполняет сам по ссылке или вы за него
A6: 1 | B6: Как тебя зовут? 💜 | C6: Короткий ответ | D6: Подсказка в поле: Имя | E6: =COUNTA(G6:P6) | F6: Юлия Ким
A7: 2 | B7: Твой город 📍 | C7: Короткий ответ | D7: Подсказка в поле: Казань | E7: =COUNTA(G7:P7) | F7: Новосибирск
A8: 3 | B8: Ты пользуешься Евой? | C8: Один вариант | D8: 💜 Да, давно · 🌱 Недавно начала · 👀 Ещё нет | E8: =COUNTA(G8:P8) | F8: 🌱 Недавно начала
A9: 4 | B9: Где твоя аудитория? 📱 | C9: Несколько вариантов | D9: Telegram · ВКонтакте · YouTube · Instagram* · TikTok · Дзен · Мамские и женские чаты · Офлайн-сообщество · Коллеги и друзья | E9: =COUNTA(G9:P9) | F9: Telegram, ВКонтакте, Коллеги и друзья
A10: 5 | B10: Сколько людей тебя читает? 👥 | C10: Один вариант | D10: До 500 · 500–3 000 · 3–10 тыс. · 10–50 тыс. · Больше 50 тыс. | E10: =COUNTA(G10:P10) | F10: 10–50 тыс.
A11: 6 | B11: О чём твой блог или сообщество? | C11: Несколько вариантов (до 3) | D11: 👶 Материнство · 💄 Красота · 🏃‍♀️ Спорт · 🧠 Психология · 💼 Бизнес · 🌿 Лайфстайл · ✈️ Путешествия · 📚 Образование | E11: =COUNTA(G11:P11) | F11: 💼 Бизнес, 👶 Материнство
A12: 7 | B12: Кто тебя читает? | C12: Один вариант | D12: В основном женщины · Примерно поровну · В основном мужчины | E12: =COUNTA(G12:P12) | F12: В основном женщины
A13: 8 | B13: Как хочешь рассказывать о Еве? 📣 | C13: Несколько вариантов | D13: 📸 Посты и сторис · 💬 Личные рекомендации · 👭 В чатах · 📡 Эфиры · 🏠 Офлайн-встречи · ⭐ Отзывы | E13: =COUNTA(G13:P13) | F13: 📸 Посты и сторис, 📡 Эфиры, 🏠 Офлайн-встречи
A14: 9 | B14: Сколько времени в неделю готова уделять? | C14: Один вариант | D14: 1 час · 2–4 часа · Больше 4 часов | E14: =COUNTA(G14:P14) | F14: 2–4 часа
A15: 10 | B15: Что для тебя главное? ✨ | C15: Несколько вариантов (до 2) | D15: 💰 Деньги · 💜 Бесплатная подписка · 🏆 Статус и признание · 👭 Сообщество · 🎓 Рост и обучение | E15: =COUNTA(G15:P15) | F15: 👭 Сообщество, 💜 Бесплатная подписка
A16: 11 | B16: Твой статус — это нужно для выплат 🧾 | C16: Один вариант | D16: Самозанятая · ИП · Пока нет | E16: =COUNTA(G16:P16) | F16: ИП
A17: 12 | B17: Как удобнее получать вознаграждение? | C17: Один вариант | D17: 💳 На карту · 💜 На баланс Евы (+10%) | E17: =COUNTA(G17:P17) | F17: 💳 На карту
... A19: 14 | B19: Твой Telegram или телефон 📲 | C19: Короткий ответ | D19: Подсказка в поле: @username или +7… | E19: =COUNTA(G19:P19) | F19: @yuliya
B20: 2. СОЗВОН — открытые вопросы для Zoom, 20–30 минут. Записывайте коротко, своими словами
B21: Дата созвона | C21: Дата | D21: Например: 25.09.2026 | E21: =COUNTA(G21:P21)
B22: Кто вёл | C22: Короткий ответ | D22: Имя из команды | E22: =COUNTA(G22:P22)
A23: 1 | B23: Почему тебе откликается Ева? Что лично тебе она дала или могла бы дать? | C23: Открытый ответ | D23: Зачем: Искренняя мотивация — основа рекомендаций | E23: =COUNTA(G23:P23)
A24: 2 | B24: Кто твоя аудитория и что у неё сейчас болит? | C24: Открытый ответ | D24: Зачем: Какой оффер ей зайдёт | E24: =COUNTA(G24:P24)
A25: 3 | B25: Как ты обычно рекомендуешь продукты? Что никогда не стала бы рекламировать? | C25: Открытый ответ | D25: Зачем: Формат и границы | E25: =COUNTA(G25:P25)
A26: 4 | B26: Какие материалы тебе нужны: тексты, видео, промокоды, эфир с экспертом? | C26: Открытый ответ | D26: Зачем: Набор амбассадора | E26: =COUNTA(G26:P26)
A27: 5 | B27: Что тебя мотивирует больше: деньги, подписка, статус, сообщество? | C27: Открытый ответ | D27: Зачем: Как вознаграждать | E27: =COUNTA(G27:P27)
A28: 6 | B28: Какой опыт партнёрских программ у тебя был? Что раздражало? | C28: Открытый ответ | D28: Зачем: Чего не повторять | E28: =COUNTA(G28:P28)
A29: 7 | B29: Сколько человек ты можешь привести за месяц — честно? | C29: Открытый ответ | D29: Зачем: Реальный прогноз | E29: =COUNTA(G29:P29)
A30: 8 | B30: Как тебе удобнее отчитываться и получать выплаты? | C30: Открытый ответ | D30: Зачем: Простая механика выплат | E30: =COUNTA(G30:P30)
A31: 9 | B31: Что может тебя разочаровать в сотрудничестве с нами? | C31: Открытый ответ | D31: Зачем: Риски | E31: =COUNTA(G31:P31)
A32: 10 | B32: Кого ещё ты бы позвала в амбассадоры? | C32: Открытый ответ | D32: Зачем: Следующие амбассадоры | E32: =COUNTA(G32:P32)
A33: + | B33: Что ещё важного прозвучало | C33: Открытый ответ | D33: Всё, что не попало в вопросы | E33: =COUNTA(G33:P33)
B34: 3. ИТОГ — сразу после созвона
B35: Решение | C35: Один вариант | D35: Подключаем · Думает · Не сейчас | E35: =COUNTA(G35:P35) | F35: Подключаем
B36: О чём договорились | C36: Несколько вариантов | D36: 🔗 Ссылка выдана · 📦 Материалы отправлены · 💜 Подписка в подарок · 🧾 Оформляет самозанятость · 📡 Эфир с экспертом · 👭 Позовёт подруг-амбассадоров | E36: =COUNTA(G36:P36) | F36: 🔗 Ссылка выдана, 📦 Материалы отправлены, 💜 Подписка в подарок
B37: Следующий шаг | C37: Короткий ответ | D37: Например: выдать материалы | E37: =COUNTA(G37:P37) | F37: Первый пост в канале
B38: Когда | C38: Дата | D38: Например: 10.10.2026 | E38: =COUNTA(G38:P38)
B39: Заметка | C39: Развёрнутый ответ | D39: Условия, договорённости, что важно помнить | E39: =COUNTA(G39:P39)

Sheet Списки
A1: Россия | B1: Полная занятость по трудовому договору | C1: Работаю удалённо | D1: Крайне низкий | E1: Собственное жильё | F1: Жаворонок — легко встаю рано | G1: Отношения | H1: Ментальное здоровье и эмоциональный баланс | I1: 5–10 минут | J1: Утром | K1: До 3 000 ₽ | L1: С наставником | M1: До 6:00 | N1: До 22:00 | O1: Ем всё | P1: До 2 часов | Q1: До 5 минут | R1: Нет, смотрю как есть | S1: Да, важно, чтобы ответили | T1: До 1 000 ₽ | U1: Telegram | V1: Да, в будни днём | W1: Инсайты собраны | X1: до года | Y1: Диплом по профилю | Z1: 🔥 Да, уже есть идея | AA1: 🏙 Приеду в студию в Москве | AB1: 1 день | AC1: Пока нет | AD1: До 3 000 ₽ | AE1: Подключаем | AF1: 💅 Салон красоты | AG1: До 100 | AH1: Пока нет | AI1: В будни утром | AJ1: Подключаем | AK1: 💜 Да, давно | AL1: До 500 | AM1: В основном женщины | AN1: 1 час | AO1: Самозанятая | AP1: 💳 На карту | AQ1: Да | AR1: Подключаем
A2: Казахстан | B2: Частичная занятость | C2: Работаю на гибридном графике | D2: Низкий | E2: Собственное жильё в ипотеке | F2: Сова — оживаю к вечеру | G2: Семья и дети | H2: Физическое здоровье, тело и тонус | I2: 15–20 минут | J2: Днём | K2: 3 000–7 000 ₽ | L2: Самостоятельно | M2: 6:00–7:00 | N2: 22:00–23:00 | O2: Вегетарианка | P2: 2–4 часа | Q2: 5–15 минут | R2: Да, 1,25–1,5× | S2: Иногда | T2: 1 000–3 000 ₽ | U2: ВКонтакте | V2: Да, в будни вечером | W2: Готова помогать ещё | X2: 1–3 года | Y2: Сертификаты и курсы | Z2: 🤔 Возможно, обсудим | AA2: 🎥 Есть своя качественная съёмка | AB2: 2–3 дня | AC2: До 1 тыс. | AD2: 3 000–6 000 ₽ | AE2: Думает | AF2: 🤸‍♀️ Студия пилатеса | AG2: 100–500 | AH2: До 1 тыс. | AI2: В будни днём | AJ2: Думает | AK2: 🌱 Недавно начала | AL2: 500–3 000 | AM2: Примерно поровну | AN2: 2–4 часа | AO2: ИП | AP2: 💜 На баланс Евы (+10%) | AQ2: Нет | AR2: Думает
A3: Беларусь | B3: Индивидуальный предприниматель | C3: Работаю в офисе 5/2 | D3: Ниже среднего | E3: Снимаю жильё | F3: Где-то посередине | G3: Карьера и учёба | H3: Романтические отношения и личная жизнь | I3: 30 минут и больше | J3: Вечером | K3: 7 000–15 000 ₽ | L3: В группе, с поддержкой | M3: 7:00–8:00 | N3: 23:00–00:00 | O3: Веганка | P3: 4–6 часов | Q3: 15–30 минут | R3: Да, 1,75–2× | S3: Нет, хватит выжимки | T3: 3 000–5 000 ₽ | U3: Блогер | V3: Да, в выходные | X3: 3–5 лет | Y3: Большая практика без документов | Z3: 📦 Есть готовый — хочу разместить | AA3: 💻 Только онлайн | AB3: Регулярно, раз в месяц | AC3: 1–10 тыс. | AD3: 6 000–10 000 ₽ | AE3: Не сейчас | AF3: 🧘‍♀️ Йога-студия | AG3: 500–2 000 | AH3: 1–10 тыс. | AI3: Вечером | AJ3: Не сейчас | AK3: 👀 Ещё нет | AL3: 3–10 тыс. | AM3: В основном мужчины | AN3: Больше 4 часов | AO3: Пока нет | AR3: Не сейчас
A4: Узбекистан | B4: Самозанятая / Фрилансер | C4: Работаю по сменному графику, например 2/2 | D4: Средний | E4: Живу с родителями или родственниками | F4: Свой режим, всё по ситуации | G4: Поиск себя и отдых | H4: Материнство и семья | K4: 15 000–30 000 ₽ | L4: По-разному | M4: 8:00–9:00 | N4: 00:00–01:00 | O4: Пескетарианка | P4: Больше 6 часов | Q4: 30–60 минут | R4: Зависит от спикера | T4: 5 000–7 000 ₽ | U4: Подруга | V4: Лучше перепишемся | X4: 5–10 лет | Z4: 🙅‍♀️ Пока нет | AA4: 🤝 Обсудим | AC4: 10–50 тыс. | AD4: Больше 10 000 ₽ | AF4: 🏋️‍♀️ Фитнес-клуб | AG4: Больше 2 000 | AH4: Больше 10 тыс. | AI4: Лучше в переписке | AL4: 10–50 тыс.
A5: Грузия | B5: Владелица бизнеса / Предприниматель | D5: Выше среднего | E5: Живу в общежитии | F5: Режим скачет: дети, смены, перелёты | H5: Карьера, бизнес и финансовая независимость | K5: 30 000–60 000 ₽ | M5: После 9:00 | N5: После 01:00 | O5: Фрукторианка | P5: Не знаю | Q5: Больше часа | T5: 7 000–10 000 ₽ | U5: Эксперт | V5: Нет, спасибо | X5: больше 10 лет | AC5: Больше 50 тыс. | AD5: Не консультирую | AF5: ✨ Косметология | AL5: Больше 50 тыс.
A6: Армения | B6: Руководитель / Топ-менеджер | D6: Высокий | E6: Служебное жильё | H6: Окружение и социальные связи | K6: 60 000 ₽ и больше | M6: Каждый день по-разному | N6: По-разному | O6: Слежу: ПП, без сахара или глютена | T6: 10 000 ₽ и больше | U6: Студия или салон | AF6: 💆‍♀️ SPA и массаж
B7: Специалист / Линейный сотрудник | D7: На обеспечении | E7: Временное размещение | H7: Личностный рост и самоопределение | U7: Мероприятие | AF7: 🥗 Здоровое питание
B8: Обслуживающий / Технический персонал | H8: Время для себя и яркость жизни | AF8: 🧠 Психологический центр
B9: Студентка | H9: В своём прайме, всё хорошо | AF9: 🏥 Женское здоровье
B10: В декретном отпуске | AF10: 👶 Центр для мам и детей
B11: Домохозяйка | AF11: 🏠 Пространство для встреч
B12: Временно не работаю | AF12: 🛍 Бренд для маркета
B13: Не работаю | AF13: 🎤 Организатор мероприятий
AF14: ⭐ Спонсор
AF15: 📱 Медиа и блогеры
AF16: 📚 Образование
